Workbook

Sheet Mode d'emploi
A1: Déroulé des modules
A2: Une ligne par étape, dans l'ordre réel des slides de chaque deck. La colonne « Type » dit ce qu'est chaque ligne, et la couleur le répète : voir la légende en bas de cette page.
A4: Ce qui se saisit (cellules jaunes)
A5: Déroulé, colonne « Durée (min) » : la durée de l'étape, en minutes. Les démonstrations sont préremplies avec la borne haute de leur page de garde (« 12 à 15 minutes » donne 15) ; la page de garde reste visible dans « Durée prévue (démo) ».
A6: Déroulé, colonne « Remarques » : libre.
A7: Synthèse, cellule C3 : un rythme en minutes par slide. Il sert d'estimation pour les lignes « Slides » sans durée saisie ; vide, ces lignes comptent 0.
A9: Ce qui se calcule
A10: « Nb slides », « Durée retenue », « Cumul module » et toute la Synthèse sont des formules : modifiez une durée, les totaux suivent.
A11: « Étapes sans durée » compte, par module, les étapes encore vides (sections exclues).
A13: Régénération
A14: python3 _outils/extraire_deroule.py relit les decks et réécrit ce classeur. Les durées, les remarques et le rythme déjà saisis sont conservés : une étape est reconnue par son module, son type et sa première slide. Si une slide est insérée avant une étape, sa première slide change, et sa saisie est à refaire.
A16: Les types de ligne (colonne « Type » du Déroulé)
... A20: Exercices : une slide d'exercices, avec les codes à faire

Sheet Synthèse
A1: Synthèse du déroulé
A3: Rythme des slides, en minutes par slide (hypothèse à saisir)
A5: Module | B5: Slides | C5: Démonstrations (min) | D5: Exercices (min) | E5: Slides (min) | F5: Total (min) | G5: Total (h:mm) | H5: Étapes sans durée
A6: INI | B6: 26 | C6: =SUMIFS(Déroulé!$J$2:$J$301,Déroulé!$A$2:$A$301,A6,Déroulé!$C$2:$C$301,"Démonstration") -> 0 | D6: =SUMIFS(Déroulé!$J$2:$J$301,Déroulé!$A$2:$A$301,A6,Déroulé!$C$2:$C$301,"Exercices") -> 0 | E6: =SUMIFS(Déroulé!$J$2:$J$301,Déroulé!$A$2:$A$301,A6,Déroulé!$C$2:$C$301,"Slides") -> 0 | F6: =C6+D6+E6 -> 0 | G6: =F6/1440 -> 0 | H6: =COUNTIFS(Déroulé!$A$2:$A$301,A6,Déroulé!$H$2:$H$301,"",Déroulé!$C$2:$C$301,"<>Section") -> 2
A7: POO | B7: 59 | C7: =SUMIFS(Déroulé!$J$2:$J$301,Déroulé!$A$2:$A$301,A7,Déroulé!$C$2:$C$301,"Démonstration") -> 25 | D7: =SUMIFS(Déroulé!$J$2:$J$301,Déroulé!$A$2:$A$301,A7,Déroulé!$C$2:$C$301,"Exercices") -> 0 | E7: =SUMIFS(Déroulé!$J$2:$J$301,Déroulé!$A$2:$A$301,A7,Déroulé!$C$2:$C$301,"Slides") -> 0 | F7: =C7+D7+E7 -> 25 | G7: =F7/1440 -> 0.017361111 | H7: =COUNTIFS(Déroulé!$A$2:$A$301,A7,Déroulé!$H$2:$H$301,"",Déroulé!$C$2:$C$301,"<>Section") -> 18
A8: TMP | B8: 48 | C8: =SUMIFS(Déroulé!$J$2:$J$301,Déroulé!$A$2:$A$301,A8,Déroulé!$C$2:$C$301,"Démonstration") -> 12 | D8: =SUMIFS(Déroulé!$J$2:$J$301,Déroulé!$A$2:$A$301,A8,Déroulé!$C$2:$C$301,"Exercices") -> 0 | E8: =SUMIFS(Déroulé!$J$2:$J$301,Déroulé!$A$2:$A$301,A8,Déroulé!$C$2:$C$301,"Slides") -> 0 | F8: =C8+D8+E8 -> 12 | G8: =F8/1440 -> 0.0083333333 | H8: =COUNTIFS(Déroulé!$A$2:$A$301,A8,Déroulé!$H$2:$H$301,"",Déroulé!$C$2:$C$301,"<>Section") -> 20
A9: TAB | B9: 27 | C9: =SUMIFS(Déroulé!$J$2:$J$301,Déroulé!$A$2:$A$301,A9,Déroulé!$C$2:$C$301,"Démonstration") -> 20 | D9: =SUMIFS(Déroulé!$J$2:$J$301,Déroulé!$A$2:$A$301,A9,Déroulé!$C$2:$C$301,"Exercices") -> 0 | E9: =SUMIFS(Déroulé!$J$2:$J$301,Déroulé!$A$2:$A$301,A9,Déroulé!$C$2:$C$301,"Slides") -> 0 | F9: =C9+D9+E9 -> 20 | G9: =F9/1440 -> 0.013888889 | H9: =COUNTIFS(Déroulé!$A$2:$A$301,A9,Déroulé!$H$2:$H$301,"",Déroulé!$C$2:$C$301,"<>Section") -> 11
A10: ENU | B10: 40 | C10: =SUMIFS(Déroulé!$J$2:$J$301,Déroulé!$A$2:$A$301,A10,Déroulé!$C$2:$C$301,"Démonstration") -> 10 | D10: =SUMIFS(Déroulé!$J$2:$J$301,Déroulé!$A$2:$A$301,A10,Déroulé!$C$2:$C$301,"Exercices") -> 0 | E10: =SUMIFS(Déroulé!$J$2:$J$301,Déroulé!$A$2:$A$301,A10,Déroulé!$C$2:$C$301,"Slides") -> 0 | F10: =C10+D10+E10 -> 10 | G10: =F10/1440 -> 0.0069444444 | H10: =COUNTIFS(Déroulé!$A$2:$A$301,A10,Déroulé!$H$2:$H$301,"",Déroulé!$C$2:$C$301,"<>Section") -> 13
A11: ABS | B11: 46 | C11: =SUMIFS(Déroulé!$J$2:$J$301,Déroulé!$A$2:$A$301,A11,Déroulé!$C$2:$C$301,"Démonstration") -> 12 | D11: =SUMIFS(Déroulé!$J$2:$J$301,Déroulé!$A$2:$A$301,A11,Déroulé!$C$2:$C$301,"Exercices") -> 0 | E11: =SUMIFS(Déroulé!$J$2:$J$301,Déroulé!$A$2:$A$301,A11,Déroulé!$C$2:$C$301,"Slides") -> 0 | F11: =C11+D11+E11 -> 12 | G11: =F11/1440 -> 0.0083333333 | H11: =COUNTIFS(Déroulé!$A$2:$A$301,A11,Déroulé!$H$2:$H$301,"",Déroulé!$C$2:$C$301,"<>Section") -> 15
A12: ITF | B12: 38 | C12: =SUMIFS(Déroulé!$J$2:$J$301,Déroulé!$A$2:$A$301,A12,Déroulé!$C$2:$C$301,"Démonstration") -> 12 | D12: =SUMIFS(Déroulé!$J$2:$J$301,Déroulé!$A$2:$A$301,A12,Déroulé!$C$2:$C$301,"Exercices") -> 0 | E12: =SUMIFS(Déroulé!$J$2:$J$301,Déroulé!$A$2:$A$301,A12,Déroulé!$C$2:$C$301,"Slides") -> 0 | F12: =C12+D12+E12 -> 12 | G12: =F12/1440 -> 0.0083333333 | H12: =COUNTIFS(Déroulé!$A$2:$A$301,A12,Déroulé!$H$2:$H$301,"",Déroulé!$C$2:$C$301,"<>Section") -> 11
A13: PKG | B13: 31 | C13: =SUMIFS(Déroulé!$J$2:$J$301,Déroulé!$A$2:$A$301,A13,Déroulé!$C$2:$C$301,"Démonstration") -> 25 | D13: =SUMIFS(Déroulé!$J$2:$J$301,Déroulé!$A$2:$A$301,A13,Déroulé!$C$2:$C$301,"Exercices") -> 0 | E13: =SUMIFS(Déroulé!$J$2:$J$301,Déroulé!$A$2:$A$301,A13,Déroulé!$C$2:$C$301,"Slides") -> 0 | F13: =C13+D13+E13 -> 25 | G13: =F13/1440 -> 0.017361111 | H13: =COUNTIFS(Déroulé!$A$2:$A$301,A13,Déroulé!$H$2:$H$301,"",Déroulé!$C$2:$C$301,"<>Section") -> 12
A14: COL | B14: 38 | C14: =SUMIFS(Déroulé!$J$2:$J$301,Déroulé!$A$2:$A$301,A14,Déroulé!$C$2:$C$301,"Démonstration") -> 12 | D14: =SUMIFS(Déroulé!$J$2:$J$301,Déroulé!$A$2:$A$301,A14,Déroulé!$C$2:$C$301,"Exercices") -> 0 | E14: =SUMIFS(Déroulé!$J$2:$J$301,Déroulé!$A$2:$A$301,A14,Déroulé!$C$2:$C$301,"Slides") -> 0 | F14: =C14+D14+E14 -> 12 | G14: =F14/1440 -> 0.0083333333 | H14: =COUNTIFS(Déroulé!$A$2:$A$301,A14,Déroulé!$H$2:$H$301,"",Déroulé!$C$2:$C$301,"<>Section") -> 13
A15: EXC | B15: 26 | C15: =SUMIFS(Déroulé!$J$2:$J$301,Déroulé!$A$2:$A$301,A15,Déroulé!$C$2:$C$301,"Démonstration") -> 12 | D15: =SUMIFS(Déroulé!$J$2:$J$301,Déroulé!$A$2:$A$301,A15,Déroulé!$C$2:$C$301,"Exercices") -> 0 | E15: =SUMIFS(Déroulé!$J$2:$J$301,Déroulé!$A$2:$A$301,A15,Déroulé!$C$2:$C$301,"Slides") -> 0 | F15: =C15+D15+E15 -> 12 | G15: =F15/1440 -> 0.0083333333 | H15: =COUNTIFS(Déroulé!$A$2:$A$301,A15,Déroulé!$H$2:$H$301,"",Déroulé!$C$2:$C$301,"<>Section") -> 11
A16: JUN | B16: 34 | C16: =SUMIFS(Déroulé!$J$2:$J$301,Déroulé!$A$2:$A$301,A16,Déroulé!$C$2:$C$301,"Démonstration") -> 15 | D16: =SUMIFS(Déroulé!$J$2:$J$301,Déroulé!$A$2:$A$301,A16,Déroulé!$C$2:$C$301,"Exercices") -> 0 | E16: =SUMIFS(Déroulé!$J$2:$J$301,Déroulé!$A$2:$A$301,A16,Déroulé!$C$2:$C$301,"Slides") -> 0 | F16: =C16+D16+E16 -> 15 | G16: =F16/1440 -> 0.010416667 | H16: =COUNTIFS(Déroulé!$A$2:$A$301,A16,Déroulé!$H$2:$H$301,"",Déroulé!$C$2:$C$301,"<>Section") -> 9
A17: GEN | B17: 32 | C17: =SUMIFS(Déroulé!$J$2:$J$301,Déroulé!$A$2:$A$301,A17,Déroulé!$C$2:$C$301,"Démonstration") -> 12 | D17: =SUMIFS(Déroulé!$J$2:$J$301,Déroulé!$A$2:$A$301,A17,Déroulé!$C$2:$C$301,"Exercices") -> 0 | E17: =SUMIFS(Déroulé!$J$2:$J$301,Déroulé!$A$2:$A$301,A17,Déroulé!$C$2:$C$301,"Slides") -> 0 | F17: =C17+D17+E17 -> 12 | G17: =F17/1440 -> 0.0083333333 | H17: =COUNTIFS(Déroulé!$A$2:$A$301,A17,Déroulé!$H$2:$H$301,"",Déroulé!$C$2:$C$301,"<>Section") -> 15
... A22: FIC | B22: 26 | C22: =SUMIFS(Déroulé!$J$2:$J$301,Déroulé!$A$2:$A$301,A22,Déroulé!$C$2:$C$301,"Démonstration") -> 25 | D22: =SUMIFS(Déroulé!$J$2:$J$301,Déroulé!$A$2:$A$301,A22,Déroulé!$C$2:$C$301,"Exercices") -> 0 | E22: =SUMIFS(Déroulé!$J$2:$J$301,Déroulé!$A$2:$A$301,A22,Déroulé!$C$2:$C$301,"Slides") -> 0 | F22: =C22+D22+E22 -> 25 | G22: =F22/1440 -> 0.017361111 | H22: =COUNTIFS(Déroulé!$A$2:$A$301,A22,Déroulé!$H$2:$H$301,"",Déroulé!$C$2:$C$301,"<>Section") -> 9
A23: Total | B23: =SUM(B6:B22) -> 584 | C23: =SUM(C6:C22) -> 222 | D23: =SUM(D6:D22) -> 0 | E23: =SUM(E6:E22) -> 0 | F23: =SUM(F6:F22) -> 222 | G23: =SUM(G6:G22) -> 0.15416667 | H23: =SUM(H6:H22) -> 193

Sheet Déroulé
A1: Module | B1: N° | C1: Type | D1: De | E1: À | F1: Nb slides | G1: Étape | H1: Durée (min) | I1: Durée prévue (démo) | J1: Durée retenue (min) | K1: Cumul module (min) | L1: Remarques
A2: INI | B2: 1 | C2: Slides | D2: 2 | E2: 17 | F2: =E2-D2+1 -> 16 | G2: Au programme ; Qui suis-je? ; Contenu du cours ; Les modules du cours ; Critères de réussite et acquis d'apprentissage ; En d'autres termes, vous devez pouvoir… ; L'organisation pratique du cours ; … et l'examen? ; Le déroulé d'un module ; Les fascicules d'exercices ; Le projet ExercicesJava ; Les tests fournis ; Le fil rouge GameHub ; Le support imprimable | J2: =IF(H2<>"",H2,IF(C2="Slides",F2*Synthèse!$C$3,0)) -> 0 | K2: =SUMIFS($J$2:J2,$A$2:A2,A2) -> 0
A3: INI | B3: 2 | C3: Section | D3: 18 | E3: 18 | G3: Section 3. Les mémentos | J3: =IF(H3<>"",H3,IF(C3="Slides",F3*Synthèse!$C$3,0)) -> 0 | K3: =SUMIFS($J$2:J3,$A$2:A3,A3) -> 0
A4: INI | B4: 3 | C4: Slides | D4: 19 | E4: 26 | F4: =E4-D4+1 -> 8 | G4: Quatre documents de référence ; Le mémento Exercices ; Le guide IntelliJ ; Le mémento technique ; Le mémento Clean Code ; Comment lire un renvoi ; Quelques liens utiles ; En résumé… | J4: =IF(H4<>"",H4,IF(C4="Slides",F4*Synthèse!$C$3,0)) -> 0 | K4: =SUMIFS($J$2:J4,$A$2:A4,A4) -> 0
A5: POO | B5: 1 | C5: Slides | D5: 2 | E5: 2 | F5: =E5-D5+1 -> 1 | G5: Au programme | J5: =IF(H5<>"",H5,IF(C5="Slides",F5*Synthèse!$C$3,0)) -> 0 | K5: =SUMIFS($J$2:J5,$A$2:A5,A5) -> 0
A6: POO | B6: 2 | C6: Section | D6: 3 | E6: 3 | G6: Section 1. De C# à Java | J6: =IF(H6<>"",H6,IF(C6="Slides",F6*Synthèse!$C$3,0)) -> 0 | K6: =SUMIFS($J$2:J6,$A$2:A6,A6) -> 0
A7: POO | B7: 3 | C7: Slides | D7: 4 | E7: 12 | F7: =E7-D7+1 -> 9 | G7: Pas de grosses différences niveau langage ; Structuration des classes ; Conventions de nommage différentes ; Lien entre fichier et classe ; Classes du Framework différentes ; Méthode main rend la classe exécutable ; Classe Java et Programme (exécutable) Java ; Du code source au programme ; En résumé… | J7: =IF(H7<>"",H7,IF(C7="Slides",F7*Synthèse!$C$3,0)) -> 0 | K7: =SUMIFS($J$2:J7,$A$2:A7,A7) -> 0
A8: POO | B8: 4 | C8: Section | D8: 13 | E8: 13 | G8: Section 2. Classe et objet | J8: =IF(H8<>"",H8,IF(C8="Slides",F8*Synthèse!$C$3,0)) -> 0 | K8: =SUMIFS($J$2:J8,$A$2:A8,A8) -> 0
A9: POO | B9: 5 | C9: Slides | D9: 14 | E9: 15 | F9: =E9-D9+1 -> 2 | G9: Les quatre principes de la POO ; Classe et objet | J9: =IF(H9<>"",H9,IF(C9="Slides",F9*Synthèse!$C$3,0)) -> 0 | K9: =SUMIFS($J$2:J9,$A$2:A9,A9) -> 0
A10: POO | B10: 6 | C10: Démonstration | D10: 16 | E10: 16 | G10: Démonstration Demo_POO : Construire une classe, puis l'encapsuler (avant POO.1) | H10: 15 | I10: 12 à 15 minutes | J10: =IF(H10<>"",H10,IF(C10="Slides",F10*Synthèse!$C$3,0)) -> 15 | K10: =SUMIFS($J$2:J10,$A$2:A10,A10) -> 15
A11: POO | B11: 7 | C11: Slides | D11: 17 | E11: 20 | F11: =E11-D11+1 -> 4 | G11: Le constructeur ; Le mot-clé this ; Un champ final ; La méthode toString | J11: =IF(H11<>"",H11,IF(C11="Slides",F11*Synthèse!$C$3,0)) -> 0 | K11: =SUMIFS($J$2:J11,$A$2:A11,A11) -> 15
A12: POO | B12: 8 | C12: Exercices | D12: 21 | E12: 21 | G12: Exercices : POO.1 Une première classe ; G.1 Le joueur ; G.2 La partie — Nommer : CC-NOM.1 et CC-NOM.5 | J12: =IF(H12<>"",H12,IF(C12="Slides",F12*Synthèse!$C$3,0)) -> 0 | K12: =SUMIFS($J$2:J12,$A$2:A12,A12) -> 15
A13: POO | B13: 9 | C13: Section | D13: 22 | E13: 22 | G13: Section 3. Encapsulation | J13: =IF(H13<>"",H13,IF(C13="Slides",F13*Synthèse!$C$3,0)) -> 0 | K13: =SUMIFS($J$2:J13,$A$2:A13,A13) -> 15
A14: POO | B14: 10 | C14: Slides | D14: 23 | E14: 27 | F14: =E14-D14+1 -> 5 | G14: Le problème d'un champ public ; Fermer les champs, ouvrir des accesseurs ; Ce que le détour permet ; Un accesseur n'est pas une obligation ; La donnée qui n'existe pas | J14: =IF(H14<>"",H14,IF(C14="Slides",F14*Synthèse!$C$3,0)) -> 0 | K14: =SUMIFS($J$2:J14,$A$2:A14,A14) -> 15
A15: POO | B15: 11 | C15: Exercices | D15: 28 | E15: 28 | G15: Exercices : POO.2 La même classe, encapsulée ; POO.3 L'âge n'est pas une donnée à stocker — Générer les accesseurs : IDE.12 | J15: =IF(H15<>"",H15,IF(C15="Slides",F15*Synthèse!$C$3,0)) -> 0 | K15: =SUMIFS($J$2:J15,$A$2:A15,A15) -> 15
A16: POO | B16: 12 | C16: Section | D16: 29 | E16: 29 | G16: Section 4. static | J16: =IF(H16<>"",H16,IF(C16="Slides",F16*Synthèse!$C$3,0)) -> 0 | K16: =SUMIFS($J$2:J16,$A$2:A16,A16) -> 15
A17: POO | B17: 13 | C17: Slides | D17: 30 | E17: 33 | F17: =E17-D17+1 -> 4 | G17: Champs et méthodes de classe ; Champs d’objets ; Champ de classe ; Nommer un champ de classe | J17: =IF(H17<>"",H17,IF(C17="Slides",F17*Synthèse!$C$3,0)) -> 0 | K17: =SUMIFS($J$2:J17,$A$2:A17,A17) -> 15
A18: POO | B18: 14 | C18: Démonstration | D18: 34 | E18: 34 | G18: Démonstration Demo_STA : Ce qui appartient à la classe, ce qui appartient à l'objet (avant STA.1) | H18: 10 | I18: 10 minutes | J18: =IF(H18<>"",H18,IF(C18="Slides",F18*Synthèse!$C$3,0)) -> 10 | K18: =SUMIFS($J$2:J18,$A$2:A18,A18) -> 25
A19: POO | B19: 15 | C19: Slides | D19: 35 | E19: 40 | F19: =E19-D19+1 -> 6 | G19: Un compteur d'instances ; Méthodes de classe ; Une méthode statique n'a pas de this ; Les constantes ; À quoi servent les méthodes de classe ; Les fabriques | J19: =IF(H19<>"",H19,IF(C19="Slides",F19*Synthèse!$C$3,0)) -> 0 | K19: =SUMIFS($J$2:J19,$A$2:A19,A19) -> 25
A20: POO | B20: 16 | C20: Exercices | D20: 41 | E20: 41 | G20: Exercices : STA.1 Une constante et un compteur d'instances ; STA.2 Un constructeur privé et des fabriques — Le débogueur : IDE.19 | J20: =IF(H20<>"",H20,IF(C20="Slides",F20*Synthèse!$C$3,0)) -> 0 | K20: =SUMIFS($J$2:J20,$A$2:A20,A20) -> 25
A21: POO | B21: 17 | C21: Section | D21: 42 | E21: 42 | G21: Section 5. Entrée de données au clavier | J21: =IF(H21<>"",H21,IF(C21="Slides",F21*Synthèse!$C$3,0)) -> 0 | K21: =SUMIFS($J$2:J21,$A$2:A21,A21) -> 25
A22: POO | B22: 18 | C22: Slides | D22: 43 | E22: 47 | F22: =E22-D22+1 -> 5 | G22: Pour les entrées au clavier, on utilise la classe Scanner… ; La Javadoc ; La documentation de Scanner ; Les principales méthodes de Scanner ; Un piège : nextInt suivi de nextLine | J22: =IF(H22<>"",H22,IF(C22="Slides",F22*Synthèse!$C$3,0)) -> 0 | K22: =SUMIFS($J$2:J22,$A$2:A22,A22) -> 25
A23: POO | B23: 19 | C23: Exercices | D23: 48 | E23: 48 | G23: Exercices : POO.4 Saisie au clavier, première partie seulement ; G.3 Le point d'entrée | J23: =IF(H23<>"",H23,IF(C23="Slides",F23*Synthèse!$C$3,0)) -> 0 | K23: =SUMIFS($J$2:J23,$A$2:A23,A23) -> 25
A24: POO | B24: 20 | C24: Section | D24: 49 | E24: 49 | G24: Section 6. Primitifs et références | J24: =IF(H24<>"",H24,IF(C24="Slides",F24*Synthèse!$C$3,0)) -> 0 | K24: =SUMIFS($J$2:J24,$A$2:A24,A24) -> 25
A25: POO | B25: 21 | C25: Slides | D25: 50 | E25: 51 | F25: =E25-D25+1 -> 2 | G25: Types primitifs vs Objets ; Deux noms, un seul objet | J25: =IF(H25<>"",H25,IF(C25="Slides",F25*Synthèse!$C$3,0)) -> 0 | K25: =SUMIFS($J$2:J25,$A$2:A25,A25) -> 25
A26: POO | B26: 22 | C26: Exercices | D26: 52 | E26: 52 | G26: Exercices : POO.4 Saisie au clavier, seconde partie — Observez, puis expliquez par écrit, avant de passer à la slide suivante | J26: =IF(H26<>"",H26,IF(C26="Slides",F26*Synthèse!$C$3,0)) -> 0 | K26: =SUMIFS($J$2:J26,$A$2:A26,A26) -> 25
A27: POO | B27: 23 | C27: Slides | D27: 53 | E27: 53 | F27: =E27-D27+1 -> 1 | G27: Ce que vous avez observé | J27: =IF(H27<>"",H27,IF(C27="Slides",F27*Synthèse!$C$3,0)) -> 0 | K27: =SUMIFS($J$2:J27,$A$2:A27,A27) -> 25
A28: POO | B28: 24 | C28: Section | D28: 54 | E28: 54 | G28: Section 7. Les wrappers | J28: =IF(H28<>"",H28,IF(C28="Slides",F28*Synthèse!$C$3,0)) -> 0 | K28: =SUMIFS($J$2:J28,$A$2:A28,A28) -> 25
A29: POO | B29: 25 | C29: Slides | D29: 55 | E29: 57 | F29: =E29-D29+1 -> 3 | G29: Types primitifs et Wrappers ; Ce qu'offrent les wrappers ; Séparer le calcul du dialogue | J29: =IF(H29<>"",H29,IF(C29="Slides",F29*Synthèse!$C$3,0)) -> 0 | K29: =SUMIFS($J$2:J29,$A$2:A29,A29) -> 25
A30: POO | B30: 26 | C30: Exercices | D30: 58 | E30: 58 | G30: Exercices : POO.5 Changement de base, et logique testable — La Javadoc de Integer.parseInt(String, int) : IDE.14 | J30: =IF(H30<>"",H30,IF(C30="Slides",F30*Synthèse!$C$3,0)) -> 0 | K30: =SUMIFS($J$2:J30,$A$2:A30,A30) -> 25
A31: POO | B31: 27 | C31: Slides | D31: 59 | E31: 59 | F31: =E31-D31+1 -> 1 | G31: En résumé | J31: =IF(H31<>"",H31,IF(C31="Slides",F31*Synthèse!$C$3,0)) -> 0 | K31: =SUMIFS($J$2:J31,$A$2:A31,A31) -> 25
A32: TMP | B32: 1 | C32: Slides | D32: 2 | E32: 2 | F32: =E32-D32+1 -> 1 | G32: Au programme | J32: =IF(H32<>"",H32,IF(C32="Slides",F32*Synthèse!$C$3,0)) -> 0 | K32: =SUMIFS($J$2:J32,$A$2:A32,A32) -> 0
A33: TMP | B33: 2 | C33: Section | D33: 3 | E33: 3 | G33: Section 1. Les classes de java.time | J33: =IF(H33<>"",H33,IF(C33="Slides",F33*Synthèse!$C$3,0)) -> 0 | K33: =SUMIFS($J$2:J33,$A$2:A33,A33) -> 0
A34: TMP | B34: 3 | C34: Slides | D34: 4 | E34: 14 | F34: =E34-D34+1 -> 11 | G34: Une date, c'est plus compliqué qu'il n'y paraît ; Les trois classes du quotidien ; Laquelle choisir ? ; Tout est dans le JDK ; Fabriquer une date ; Lire un morceau de date ; Comparer deux dates ; Quelques exemples avec LocalDate ; L'heure seule ; Quelques exemples avec LocalTime ; Les deux à la fois | J34: =IF(H34<>"",H34,IF(C34="Slides",F34*Synthèse!$C$3,0)) -> 0 | K34: =SUMIFS($J$2:J34,$A$2:A34,A34) -> 0
A35: TMP | B35: 4 | C35: Démonstration | D35: 15 | E35: 15 | G35: Démonstration Demo_TMP : Explorer une classe du JDK sans quitter l'éditeur (avant TMP.1) | H35: 12 | I35: 12 minutes | J35: =IF(H35<>"",H35,IF(C35="Slides",F35*Synthèse!$C$3,0)) -> 12 | K35: =SUMIFS($J$2:J35,$A$2:A35,A35) -> 12
A36: TMP | B36: 5 | C36: Section | D36: 16 | E36: 16 | G36: Section 2. Mesurer un écart | J36: =IF(H36<>"",H36,IF(C36="Slides",F36*Synthèse!$C$3,0)) -> 0 | K36: =SUMIFS($J$2:J36,$A$2:A36,A36) -> 12
A37: TMP | B37: 6 | C37: Slides | D37: 17 | E37: 18 | F37: =E37-D37+1 -> 2 | G37: ChronoUnit, l'unité de mesure ; Deux pièges de comptage | J37: =IF(H37<>"",H37,IF(C37="Slides",F37*Synthèse!$C$3,0)) -> 0 | K37: =SUMIFS($J$2:J37,$A$2:A37,A37) -> 12
A38: TMP | B38: 7 | C38: Exercices | D38: 19 | E38: 19 | G38: Exercices : TMP.1 Mesurer un écart entre deux dates | J38: =IF(H38<>"",H38,IF(C38="Slides",F38*Synthèse!$C$3,0)) -> 0 | K38: =SUMIFS($J$2:J38,$A$2:A38,A38) -> 12
A39: TMP | B39: 8 | C39: Section | D39: 20 | E39: 20 | G39: Section 3. Une date ne change pas | J39: =IF(H39<>"",H39,IF(C39="Slides",F39*Synthèse!$C$3,0)) -> 0 | K39: =SUMIFS($J$2:J39,$A$2:A39,A39) -> 12
A40: TMP | B40: 9 | C40: Slides | D40: 21 | E40: 21 | F40: =E40-D40+1 -> 1 | G40: Décaler une date | J40: =IF(H40<>"",H40,IF(C40="Slides",F40*Synthèse!$C$3,0)) -> 0 | K40: =SUMIFS($J$2:J40,$A$2:A40,A40) -> 12
...
